Workbook

Sheet Summary
A1: PRISM CIH Web - Validation & Restriction Audit
A2: Audit date 2026-10-03 | branch dev | static review of src/app and lambda-functions/. Counts are live formulas over the detail sheets.
A4: Area | B4: Done | C4: Partial | D4: Missing | E4: Total | F4: % Done
A5: Client-side rules | B5: =COUNTIF('Client-Side'!$C$5:$C$111,"Done") | C5: =COUNTIF('Client-Side'!$C$5:$C$111,"Partial") | D5: =COUNTIF('Client-Side'!$C$5:$C$111,"Missing") | E5: =SUM(B5:D5) | F5: =IF(E5=0,0,B5/E5)
A6: Server-side: auth check per Lambda | B6: =COUNTIF('Server-Side'!$B$5:$B$32,"Done") | C6: =COUNTIF('Server-Side'!$B$5:$B$32,"Partial") | D6: =COUNTIF('Server-Side'!$B$5:$B$32,"Missing") | E6: =SUM(B6:D6) | F6: =IF(E6=0,0,B6/E6)
A7: System restrictions | B7: =COUNTIF('System Restrictions'!$C$5:$C$37,"Done") | C7: =COUNTIF('System Restrictions'!$C$5:$C$37,"Partial") | D7: =COUNTIF('System Restrictions'!$C$5:$C$37,"Missing") | E7: =SUM(B7:D7) | F7: =IF(E7=0,0,B7/E7)
A8: Total | B8: =SUM(B5:B7) | C8: =SUM(C5:C7) | D8: =SUM(D5:D7) | E8: =SUM(E5:E7) | F8: =IF(E8=0,0,B8/E8)
A10: Other counts
A11: P1 critical gaps | B11: =COUNTA('P1 Critical'!C5:C18)
A12: P1 gaps still open | B12: =COUNTIF('P1 Critical'!F5:F18,"Open")
A13: Endpoints with no source in repo | B13: =COUNTA('Missing Endpoints'!B5:B34)
A14: Lambda rows reviewed | B14: =COUNTA('Server-Side'!A5:A32)
A16: How to use
A17: - Track fixes in 'Fix Status' (P1 Critical) and 'Status' (Fix Order): Open / In progress / Fixed.
A18: - When a rule is fixed, set its Status on the detail sheet to Done; the table above recalculates.
A19: - Status values: Done, Partial, Missing, Unknown (= source not in repo).

Sheet P1 Critical
A1: Top Priority Gaps (P1)
A2: Source: docs/VALIDATION_AUDIT.md | audit date 2026-10-03 | branch dev | static code review
A4: # | B4: Priority | C4: Gap | D4: Where | E4: Impact | F4: Fix Status
A5: 1 | B5: P1 | C5: No caller / role check on the generic update endpoint | D5: prismMultiplefieldupdate.js | E5: Any user can update ROLE_PAGE_ACCESS (grant own role any page), MEM_MEMBERS (no-longer-patient flag), plans, attachments, tasks | F5: Open
A6: 2 | B6: P1 | C6: No caller / role check on the bulk update endpoint | D6: prismMultipleRowAndFieldUpdate.js | E6: Any user can set MEM_OUTREACH_MEMBERS.Care_Coordinator_id to themselves, which bypasses every ownership check in the select/gap Lambdas | F6: Open
A7: 3 | B7: P1 | C7: No caller check on prismMultipleRowInsert.js (it also lists ROLE_PAGE_ACCESS) | D7: prismMultipleRowInsert.js | E7: Anonymous inserts; non-admin can insert page-access rows (the admin gate exists only in prismMultipleinsert.js) | F7: Open
A8: 4 | B8: P1 | C8: Password reset of any account with no auth | D8: prismUpdateCognitoUser.js (TODO in code) | E8: Account takeover: anyone can set any user's Cognito password | F8: Open
A9: 5 | B9: P1 | C9: DB password update with no ownership check | D9: prismUserPasswordUpdate.js (TODO in code) | E9: Any user can change any user's DB password by ID | F9: Open
A10: 6 | B10: P1 | C10: User creation with no admin check | D10: prismCreateCognitoUser.js, prismCreateUser.js (TODO in code) | E10: Anyone can create login-capable accounts with any role_id (including Admin = 7) | F10: Open
A11: 7 | B11: P1 | C11: Attachment delete with no auth/ownership | D11: prismdeleteAttachment.js (TODO in code) | E11: Delete any attachment + S3 object by enumerating ids | F11: Open
A12: 8 | B12: P1 | C12: Lockout reset is unauthenticated | D12: loginSuccessReset.js | E12: Anyone can clear the failed-attempt counter for any user, so lockout is ineffective | F12: Open
A13: 9 | B13: P1 | C13: Stored XSS | D13: calllist-dialog.service.ts builds HTML with unescaped action_note, action_type, action_result, then bypassSecurityTrustHtml | E13: A note typed in Add Action runs script for anyone viewing call history | F13: Open
A14: 10 | B14: P1 | C14: Cognito client secret shipped in the browser bundle | D14: environments/environment.ts -> auth.service.ts calculateSecretHash | E14: Secret is public; app client should be a public client (no secret) | F14: Open
A15: 11 | B15: P1 | C15: No route guards; role/page access is client-only | D15: app.routes.ts (0 canActivate), header.service.ts | E15: Page access is checked after the component loads, from localStorage (user-editable). The real protection is only the per-Lambda checks, and items 1–7 lack them | F15: Open
A16: 12 | B16: P1 | C16: Expired password not enforced | D16: login.ts stores user + Cognito tokens before the expiry check; prismAuthentication.js still returns 200 | E16: User with an expired password can browse straight to /dashboard | F16: Open
... A18: 14 | B18: P1 | C18: Audit fields trusted from client | D18: All inserts (added_by, add_by, log_by, refer_by, ADDED_BY) | E18: MEM_SYSTEM_LOG and ownership columns can be spoofed; should be set from caller sub server-side | F18: Open

Sheet Client-Side
A1: Client-Side Validation - Page by Page
A2: Source: docs/VALIDATION_AUDIT.md | audit date 2026-10-03 | branch dev | static code review
A4: Page / Dialog | B4: Field / Rule | C4: Status | D4: Notes / What is missing
A5: Login (/login) | B5: Username, password required | C5: Done | D5: HTML required
A6: Login (/login) | B6: OTP 6 digits | C6: Done | D6: maxlength=6, pattern=[0-9]*, auto-submit at 6
A7: Login (/login) | B7: MFA (TOTP setup + verify) | C7: Done | D7: Via Cognito
A8: Login (/login) | B8: Failed-attempt counter + lock message | C8: Partial | D8: Driven by the client (loginFailedIncrement -> prismLockedCognitoUser). Skipped if the API is called directly. prismLockedCognitoUser now requires Admin, so a non-logged-in user's call will get 401/403. Verify that lockout still disables the Cognito user.
A9: Login (/login) | B9: Username email-format / trim | C9: Missing | D9: Add Validators.email + trim
A10: Login (/login) | B10: Expired password blocks login | C10: Missing | D10: See P1 #12. Do not call setUser (or keep tokens) until the expiry check passes
A11: Change Password (/change-password) | B11: New = Confirm | C11: Done
A12: Change Password (/change-password) | B12: >=15 chars, upper, lower, digit, special | C12: Done | D12: In validatePasswordPolicy
A13: Change Password (/change-password) | B13: HTML minlength="8" | C13: Partial | D13: Conflicts with the 15-char policy; change it to 15
A14: Change Password (/change-password) | B14: Special-char set | C14: Partial | D14: Client allows only !@#$%^&*; server accepts any non-alphanumeric character. Align them
A15: Change Password (/change-password) | B15: Current password required | C15: Missing
A16: Change Password (/change-password) | B16: New != old / password history | C16: Missing
A17: Change Password (/change-password) | B17: Password must not contain name/email | C17: Missing
A18: Manage Users – Add/Edit User dialog | B18: First / Last name required | C18: Done | D18: Trimmed on submit
A19: Manage Users – Add/Edit User dialog | B19: Role, Department, Status required | C19: Done
A20: Manage Users – Add/Edit User dialog | B20: Email required + format | C20: Partial | D20: Validators.email accepts a@b; server requires a dot. Use the same regex
A21: Manage Users – Add/Edit User dialog | B21: Email duplicate check | C21: Done | D21: checkuserexist (server also returns 409 on unique violation)
A22: Manage Users – Add/Edit User dialog | B22: Password | C22: Partial | D22: Only minLength(6), but the hint and server require 15 + complexity. Add the same policy validator
A23: Manage Users – Add/Edit User dialog | B23: Confirm password | C23: Missing
A24: Manage Users – Add/Edit User dialog | B24: Name max length (100) / email (150) | C24: Missing | D24: Server enforces it; client should too
A25: Manage Users – Add/Edit User dialog | B25: Name pattern (letters, space, -, ') | C25: Missing
A26: Manage Users – Add/Edit User dialog | B26: Whitespace-only names | C26: Partial | D26: Pass required; rejected by server after trim
A27: Manage Users – Add/Edit User dialog | B27: Admin cannot deactivate self or remove own Admin role | C27: Missing
A28: New User Account Request dialog | B28: First, last, email, phone, role, date, status required | C28: Done
A29: New User Account Request dialog | B29: Email format | C29: Done | D29: Same a@b weakness
A30: New User Account Request dialog | B30: Phone auto-format (xxx) xxx-xxxx, maxlength 14 | C30: Done
A31: New User Account Request dialog | B31: Phone exactly 10 digits | C31: Missing | D31: (12 passes required
A32: New User Account Request dialog | B32: Duplicate email (existing user / pending request) | C32: Missing
A33: New User Account Request dialog | B33: Request date not in future | C33: Missing
A34: New User Account Request dialog | B34: Status should not be selectable on create | C34: Missing
A35: New User Account Request dialog | B35: Names length / pattern / trim | C35: Missing
A36: New User Account Request dialog | B36: Error shown to user | C36: Missing | D36: handleError only logs to the console
A37: Alternate Address dialog | B37: Address, city, state, zip required | C37: Done
A38: Alternate Address dialog | B38: Zip auto-format, maxlength 10 | C38: Done
A39: Alternate Address dialog | B39: Zip exactly 5 or 9 digits | C39: Missing | D39: 123 passes
A40: Alternate Address dialog | B40: State = valid 2-letter code (dropdown) | C40: Missing | D40: Free text
A41: Alternate Address dialog | B41: Length limits, trim, whitespace-only | C41: Missing
...

Sheet Server-Side
A1: Server-Side Validation - Lambda by Lambda
A2: Source: docs/VALIDATION_AUDIT.md | audit date 2026-10-03 | branch dev | static code review
A4: Lambda | B4: Auth (caller sub) | C4: Role / Ownership | D4: Input validation done | E4: Missing
A5: prismAuthentication | B5: n/a (login) | C5: – | D5: username/password required; bcrypt; lock check (423); active users only | E5: Doesn't increment failed attempts itself; returns 200 when password expired; returns all roles' page access
A6: loginSuccessReset | B6: Missing | C6: Missing | D6: username required | E6: P1 #8
A7: prismLockedCognitoUser | B7: Done | C7: Done - Admin | D7: username required | E7: Conflicts with the login lockout flow (see 1.1)
A8: prismAdminUnLockedCognitoUser | B8: Done | C8: Done - Admin | D8: username required | E8: –
A9: prismUserPasswordUpdate | B9: Missing | C9: Missing | D9: ID, password required; 15-char policy | E9: P1 #5; ID integer check
A10: prismUpdateCognitoUser | B10: Missing | C10: Missing | D10: username required; attribute allow-list; policy | E10: P1 #4; returns 500 for missing username (should be 400)
A11: prismCreateCognitoUser | B11: Missing | C11: Missing | D11: email format; policy; numeric role | E11: P1 #6
A12: prismCreateUser | B12: Missing | C12: Missing | D12: required; trim; length; email; ints; status ∈ {0,1}; policy; 409 on duplicate | E12: P1 #6; role/department exist in master tables
A13: prismUpdateUser | B13: Done | C13: Done - Admin | D13: required; ints; status; optional policy | E13: Name length/trim; role/department exist; Admin can't demote self
A14: prismMultipleinsert | B14: Done | C14: Partial - Admin only for ROLE_PAGE_ACCESS | D14: table allow-list; required fields per table; identifier check; batching | E14: Column allow-list per table; member ownership for medicaid_id rows; audit fields from caller; type/format/length checks (phone, zip, email, dates); max rows; MEM_GAP_OBSERVATION_DATA and *_TEMP have no required fields; temp tables not Admin-gated
A15: prismMultipleRowInsert | B15: Missing | C15: Missing | D15: table allow-list; required fields | E15: P1 #3 (same gaps as above)
... A32: prismGetproviderIdByTin | B32: Missing | C32: Missing | D32: TIN = 9 digits | E32: Auth (low risk, reference data)

Sheet Missing Endpoints
A1: Endpoints Called by UI With No Source in Repo
A2: Source: docs/VALIDATION_AUDIT.md | audit date 2026-10-03 | branch dev | static code review
A4: # | B4: Endpoint | C4: Status | D4: Action
A5: 1 | B5: loginFailedIncrement | C5: Not in repo | D5: Add source to repo; apply auth + ownership checks
A6: 2 | B6: loginOtpInput | C6: Not in repo | D6: Add source to repo; apply auth + ownership checks
A7: 3 | B7: pismGetbenefits | C7: Not in repo | D7: Add source to repo; apply auth + ownership checks
A8: 4 | B8: prismActionresultfollowup | C8: Not in repo | D8: Add source to repo; apply auth + ownership checks
A9: 5 | B9: prismFileProcessLoglistBySession | C9: Not in repo | D9: Add source to repo; apply auth + ownership checks
A10: 6 | B10: prismFileProcesslistByType | C10: Not in repo | D10: Add source to repo; apply auth + ownership checks
A11: 7 | B11: prismGetAddActionMasterData | C11: Not in repo | D11: Add source to repo; apply auth + ownership checks
A12: 8 | B12: prismGetMemberPCPVisitList | C12: Not in repo | D12: Add source to repo; apply auth + ownership checks
A13: 9 | B13: prismGetProviderListByVendorId | C13: Not in repo | D13: Add source to repo; apply auth + ownership checks
A14: 10 | B14: prismGetStarPerformanceByYear | C14: Not in repo | D14: Add source to repo; apply auth + ownership checks
A15: 11 | B15: prismGetTempMembersBySeccionID | C15: Not in repo | D15: Add source to repo; apply auth + ownership checks
A16: 12 | B16: prismGetTempQualityGapsBySeccionID | C16: Not in repo | D16: Add source to repo; apply auth + ownership checks
... A34: 30 | B34: prismVendorMasterlist | C34: Not in repo | D34: Add source to repo; apply auth + ownership checks

Sheet System Restrictions
A1: System-Wide Restriction Checklist
A2: Source: docs/VALIDATION_AUDIT.md | audit date 2026-10-03 | branch dev | static code review
A4: Area | B4: Restriction | C4: Status | D4: Notes
A5: Authentication | B5: Cognito login + TOTP MFA | C5: Done
A6: Authentication | B6: Cognito authorizer on API Gateway for all routes | C6: Partial | D6: Confirmed on some; login-flow routes have none
A7: Authentication | B7: Client secret not in browser | C7: Missing
A8: Session | B8: 10-min inactivity logout | C8: Done
A9: Session | B9: Token refresh | C9: Done
A10: Session | B10: Tokens in localStorage (XSS-exposed) | C10: Partial
A11: Password | B11: 15+ chars & complexity on server (create / update / reset) | C11: Done
A12: Password | B12: Same policy on client (Add User) | C12: Missing | D12: (6 chars)
A13: Password | B13: Expiry warning + expiry | C13: Partial | D13: Shown, not enforced
A14: Password | B14: History / no-reuse | C14: Missing
A15: Lockout | B15: Lock after N failures | C15: Partial | D15: Client-driven; reset endpoint is open
A16: Lockout | B16: Admin unlock with note | C16: Done
A17: Authorization | B17: Role-based menu | C17: Done | D17: (UI only)
A18: Authorization | B18: Route guards | C18: Missing
A19: Authorization | B19: Server role checks | C19: Partial | D19: Done on ~60% of the Lambdas in the repo; missing on the generic update/insert and user/password endpoints
A20: Authorization | B20: Member ownership (navigator sees only own members) | C20: Partial | D20: Done on reads; bypassable through P1 #2; missing on member-level inserts
A21: Data input | B21: SQL parameterisation | C21: Done | D21: Everywhere reviewed
A22: Data input | B22: Table / id-column allow-lists | C22: Done
A23: Data input | B23: Column allow-lists | C23: Missing
A24: Data input | B24: Format checks (phone / zip / email / NPI / codes / dates) on server | C24: Missing | D24: Mostly missing
A25: Data input | B25: Length limits on server | C25: Partial | D25: Users only
A26: Files | B26: Upload: safe filename, fixed bucket, owner check | C26: Done
A27: Files | B27: Upload: type / size limits | C27: Missing
A28: Files | B28: Delete: auth / owner | C28: Missing
A29: Files | B29: CSV import: header check | C29: Done | D29: (4 of 5)
A30: Files | B30: CSV import: row validation / size limit | C30: Missing
A31: Output | B31: Angular auto-escaping | C31: Done
A32: Output | B32: bypassSecurityTrustHtml with raw data | C32: Missing | D32: Call list (XSS)
A33: Output | B33: CSV export injection escaping | C33: Missing
A34: Errors | B34: Generic 500s, no SQL leak | C34: Done | D34: Mostly (prismLockedCognitoUser echoes error.message)
A35: Audit | B35: System log written for key actions | C35: Done
A36: Audit | B36: Audit identity set server-side | C36: Missing
A37: CORS | B37: Origin allow-list | C37: Partial | D37: Upload Lambda falls back to http://localhost:4200; others depend on the shared responseHelper layer (not in repo)

Sheet Fix Order
A1: Suggested Fix Order
A2: Source: docs/VALIDATION_AUDIT.md | audit date 2026-10-03 | branch dev | static code review
A4: Step | B4: Scope | C4: Action | D4: Status
A5: 1 | B5: P1 #1–#8, #13 | C5: add the existing callerSub -> MEM_USERS -> role/ownership block (already used in prismUpdateUser.js) to every Lambda listed. | D5: Open
A6: 2 | B6: P1 #9 | C6: escape fields in calllist-dialog.service.ts (reuse escapeHtml from benefits-dialog.service.ts). | D6: Open
A7: 3 | B7: P1 #10–#12 | C7: remove the client secret (public app client), add authGuard + roleGuard on routes, and block the session when the password has expired. | D7: Open
A8: 4 | B8: P1 #14 | C8: set added_by / log_by / refer_by from the caller on the server; add per-table column allow-lists. | D8: Open
A9: 5 | B9: P2 | C9: align the client password validator, phone/zip/NPI/date validators, file type/size limits, CSV row validation, next-activity date rule. | D9: Open
A10: 6 | B10: P3 | C10: duplicate checks, length limits, user-visible error messages, CSV export escaping, remove console.log. | D10: Open
